Workbook

Sheet Company Profile
A1: PZ NIGERIA LIMITED: COMPANY PROFILE
A2: The company facts behind the PESTLE, SWOT and industry analysis in this workbook
A4: Item | B4: Details
A5: Company | B5: PZ Nigeria Limited, part of the UK-based PZ Cussons group
A6: Department | B6: Marketing Department, Ilupeju, Lagos
A7: Managing Director | B7: Mr Oghale Ogueni
A8: Chief Financial Officer | B8: Mr Oladare Oresukan
A9: Consumer business (Family Care) | B9: Imperial Leather, Premier Cool, Joy, Morning Fresh
A10: Electrical business | B10: Air conditioners, fridges and freezers, washing machines
A11: Structure | B11: Managing Director (with the CFO and HR Director) > Category Managers > Brand Managers > Assistant Brand Managers
A12: How it is organised | B12: Product and brand structure: each brand has its own manager, and shared support teams serve all the brands
A13: Industry | B13: Fast-moving consumer goods (personal care and home care) and consumer electricals
A15: What is in this workbook
A16: PESTLE | B16: Political, Economic, Social, Technological, Legal and Environmental factors, each scored Impact × Likelihood, with a summary and chart per factor
A17: SWOT | B17: Strengths, Weaknesses, Opportunities and Threats in a 2 × 2 matrix
A18: SWOT Scoring | B18: The SWOT points weighted and rated (IFE and EFE matrices) and the strategy they point to
A19: Industry Analysis | B19: Industry overview, Porter's Five Forces and the main competitors
A20: Summary | B20: The key results from every sheet, and the recommendations
A22: The ratings and weights are typed in; everything else is a formula. Change any rating or weight and every score, summary, chart and conclusion updates.

Sheet PESTLE
A1: PESTLE ANALYSIS: PZ NIGERIA LIMITED
A2: Impact and Likelihood are rated 1 (low) to 5 (high). Score = Impact × Likelihood (1 to 25). Priority: High 16 and above, Medium 9 to 15, Low below 9.
A4: Factor | B4: Issue | C4: Effect on PZ Nigeria | D4: Type | E4: Impact (1-5) | F4: Likelihood (1-5) | G4: Score | H4: Priority
A5: Political | B5: Fuel subsidy removal and FX reforms | C5: Higher fuel and transport costs; easier access to dollars over time | D5: Threat | E5: 4 | F5: 5 | G5: =E5*F5 -> 20 | H5: =IF(G5>=16,"High",IF(G5>=9,"Medium","Low")) -> High
A6: Political | B6: Import duties and levies | C6: Imported raw materials and parts cost more | D6: Threat | E6: 3 | F6: 4 | G6: =E6*F6 -> 12 | H6: =IF(G6>=16,"High",IF(G6>=9,"Medium","Low")) -> Medium
A7: Political | B7: 2027 elections and policy changes | C7: Uncertainty can delay investment and change the rules | D7: Threat | E7: 3 | F7: 3 | G7: =E7*F7 -> 9 | H7: =IF(G7>=16,"High",IF(G7>=9,"Medium","Low")) -> Medium
A8: Economic | B8: Naira devaluation and FX shortages | C8: Imported raw materials cost much more; losses on foreign-currency debts | D8: Threat | E8: 5 | F8: 5 | G8: =E8*F8 -> 25 | H8: =IF(G8>=16,"High",IF(G8>=9,"Medium","Low")) -> High
A9: Economic | B9: High inflation | C9: Shoppers buy less or switch to cheaper brands | D9: Threat | E9: 5 | F9: 5 | G9: =E9*F9 -> 25 | H9: =IF(G9>=16,"High",IF(G9>=9,"Medium","Low")) -> High
A10: Economic | B10: High interest rates | C10: Borrowing is expensive; fewer appliances bought on credit | D10: Threat | E10: 3 | F10: 4 | G10: =E10*F10 -> 12 | H10: =IF(G10>=16,"High",IF(G10>=9,"Medium","Low")) -> Medium
A11: Social | B11: Large, young, growing population | C11: A big and growing market for soaps, detergents and appliances | D11: Opportunity | E11: 4 | F11: 5 | G11: =E11*F11 -> 20 | H11: =IF(G11>=16,"High",IF(G11>=9,"Medium","Low")) -> High
A12: Social | B12: Price-sensitive shoppers | C12: Demand for smaller, cheaper packs | D12: Opportunity | E12: 4 | F12: 4 | G12: =E12*F12 -> 16 | H12: =IF(G12>=16,"High",IF(G12>=9,"Medium","Low")) -> High
A13: Social | B13: Growing hygiene awareness | C13: More demand for soaps and cleaning products | D13: Opportunity | E13: 3 | F13: 4 | G13: =E13*F13 -> 12 | H13: =IF(G13>=16,"High",IF(G13>=9,"Medium","Low")) -> Medium
A14: Technological | B14: Social media and digital marketing | C14: Cheaper, targeted adverts that reach young buyers | D14: Opportunity | E14: 3 | F14: 5 | G14: =E14*F14 -> 15 | H14: =IF(G14>=16,"High",IF(G14>=9,"Medium","Low")) -> Medium
A15: Technological | B15: E-commerce and modern retail | C15: New ways to sell: online stores and supermarkets | D15: Opportunity | E15: 3 | F15: 4 | G15: =E15*F15 -> 12 | H15: =IF(G15>=16,"High",IF(G15>=9,"Medium","Low")) -> Medium
A16: Technological | B16: Poor power supply | C16: Factories spend more on diesel and solar; demand for energy-saving appliances | D16: Threat | E16: 4 | F16: 4 | G16: =E16*F16 -> 16 | H16: =IF(G16>=16,"High",IF(G16>=9,"Medium","Low")) -> High
... A22: Environmental | B22: Demand for eco-friendly products | C22: A chance to launch greener packs and appliances | D22: Opportunity | E22: 2 | F22: 3 | G22: =E22*F22 -> 6 | H22: =IF(G22>=16,"High",IF(G22>=9,"Medium","Low")) -> Low
A23: Average score (all issues) | G23: =AVERAGE(G5:G22) -> 14.222222 | H23: =IF(G23>=16,"High",IF(G23>=9,"Medium","Low")) -> Medium
A25: PESTLE summary by factor
A26: Factor | B26: Number of issues (COUNTIF) | C26: Average score (AVERAGEIF) | D26: Highest score | E26: High priority | F26: Threats | G26: Opportunities | H26: Rank
A27: Political | B27: =COUNTIF($A$5:$A$22,A27) -> 3 | C27: =AVERAGEIF($A$5:$A$22,A27,$G$5:$G$22) -> 13.666667 | D27: =SUMPRODUCT(MAX(($A$5:$A$22=A27)*$G$5:$G$22)) -> 20 | E27: =COUNTIFS($A$5:$A$22,A27,$H$5:$H$22,"High") -> 1 | F27: =COUNTIFS($A$5:$A$22,A27,$D$5:$D$22,"Threat") -> 3 | G27: =COUNTIFS($A$5:$A$22,A27,$D$5:$D$22,"Opportunity") -> 0 | H27: =RANK(C27,$C$27:$C$32) -> 4
A28: Economic | B28: =COUNTIF($A$5:$A$22,A28) -> 3 | C28: =AVERAGEIF($A$5:$A$22,A28,$G$5:$G$22) -> 20.666667 | D28: =SUMPRODUCT(MAX(($A$5:$A$22=A28)*$G$5:$G$22)) -> 25 | E28: =COUNTIFS($A$5:$A$22,A28,$H$5:$H$22,"High") -> 2 | F28: =COUNTIFS($A$5:$A$22,A28,$D$5:$D$22,"Threat") -> 3 | G28: =COUNTIFS($A$5:$A$22,A28,$D$5:$D$22,"Opportunity") -> 0 | H28: =RANK(C28,$C$27:$C$32) -> 1
A29: Social | B29: =COUNTIF($A$5:$A$22,A29) -> 3 | C29: =AVERAGEIF($A$5:$A$22,A29,$G$5:$G$22) -> 16 | D29: =SUMPRODUCT(MAX(($A$5:$A$22=A29)*$G$5:$G$22)) -> 20 | E29: =COUNTIFS($A$5:$A$22,A29,$H$5:$H$22,"High") -> 2 | F29: =COUNTIFS($A$5:$A$22,A29,$D$5:$D$22,"Threat") -> 0 | G29: =COUNTIFS($A$5:$A$22,A29,$D$5:$D$22,"Opportunity") -> 3 | H29: =RANK(C29,$C$27:$C$32) -> 2
A30: Technological | B30: =COUNTIF($A$5:$A$22,A30) -> 3 | C30: =AVERAGEIF($A$5:$A$22,A30,$G$5:$G$22) -> 14.333333 | D30: =SUMPRODUCT(MAX(($A$5:$A$22=A30)*$G$5:$G$22)) -> 16 | E30: =COUNTIFS($A$5:$A$22,A30,$H$5:$H$22,"High") -> 1 | F30: =COUNTIFS($A$5:$A$22,A30,$D$5:$D$22,"Threat") -> 1 | G30: =COUNTIFS($A$5:$A$22,A30,$D$5:$D$22,"Opportunity") -> 2 | H30: =RANK(C30,$C$27:$C$32) -> 3
A31: Legal | B31: =COUNTIF($A$5:$A$22,A31) -> 3 | C31: =AVERAGEIF($A$5:$A$22,A31,$G$5:$G$22) -> 11.666667 | D31: =SUMPRODUCT(MAX(($A$5:$A$22=A31)*$G$5:$G$22)) -> 15 | E31: =COUNTIFS($A$5:$A$22,A31,$H$5:$H$22,"High") -> 0 | F31: =COUNTIFS($A$5:$A$22,A31,$D$5:$D$22,"Threat") -> 3 | G31: =COUNTIFS($A$5:$A$22,A31,$D$5:$D$22,"Opportunity") -> 0 | H31: =RANK(C31,$C$27:$C$32) -> 5
A32: Environmental | B32: =COUNTIF($A$5:$A$22,A32) -> 3 | C32: =AVERAGEIF($A$5:$A$22,A32,$G$5:$G$22) -> 9 | D32: =SUMPRODUCT(MAX(($A$5:$A$22=A32)*$G$5:$G$22)) -> 12 | E32: =COUNTIFS($A$5:$A$22,A32,$H$5:$H$22,"High") -> 0 | F32: =COUNTIFS($A$5:$A$22,A32,$D$5:$D$22,"Threat") -> 2 | G32: =COUNTIFS($A$5:$A$22,A32,$D$5:$D$22,"Opportunity") -> 1 | H32: =RANK(C32,$C$27:$C$32) -> 6
A33: All factors | B33: =SUM(B27:B32) -> 18 | C33: =AVERAGE(G5:G22) -> 14.222222 | D33: =MAX(G5:G22) -> 25 | E33: =SUM(E27:E32) -> 6 | F33: =SUM(F27:F32) -> 12 | G33: =SUM(G27:G32) -> 6
A35: Key findings
A36: Finding | C36: Result | G36: Excel functions
A37: Most important factor | C37: =INDEX($A$27:$A$32,MATCH(MAX($C$27:$C$32),$C$27:$C$32,0))&" (average score "&TEXT(MAX($C$27:$C$32),"0.0")&")" -> Economic (average score 20.7) | G37: INDEX, MATCH, MAX
A38: Least important factor | C38: =INDEX($A$27:$A$32,MATCH(MIN($C$27:$C$32),$C$27:$C$32,0))&" (average score "&TEXT(MIN($C$27:$C$32),"0.0")&")" -> Environmental (average score 9.0) | G38: INDEX, MATCH, MIN
A39: Highest-scoring issue | C39: =INDEX($B$5:$B$22,MATCH(MAX($G$5:$G$22),$G$5:$G$22,0))&" (score "&MAX($G$5:$G$22)&" of 25)" -> Naira devaluation and FX shortages (score 25 of 25) | G39: INDEX, MATCH, MAX
A40: High-priority issues | C40: =COUNTIF($H$5:$H$22,"High")&" of "&COUNTA($A$5:$A$22)&" issues" -> 6 of 18 issues | G40: COUNTIF, COUNTA
A41: Threats and opportunities | C41: =COUNTIF($D$5:$D$22,"Threat")&" threats, "&COUNTIF($D$5:$D$22,"Opportunity")&" opportunities" -> 12 threats, 6 opportunities | G41: COUNTIF
A43: Chart: average PESTLE score by factor

Sheet SWOT
A1: SWOT ANALYSIS: PZ NIGERIA LIMITED
A2: Strengths and weaknesses are inside the company; opportunities and threats come from outside it
B4: HELPFUL | C4: HARMFUL
A5: INTERNAL | B5: STRENGTHS | C5: WEAKNESSES
B6: 1. Well-known brands such as Imperial Leather and Joy | C6: 1. Waiting for the UK owner's approval can slow work
B7: 2. More than 100 years in Nigeria; trusted by buyers | C7: 2. Too many management levels can cause delays
B8: 3. Wide distribution network across Nigeria | C8: 3. Brands may fight over the same marketing money
B9: 4. Each business focuses on its own customers | C9: 4. Naira problems force hard decisions on imports
B10: 5. One manager per brand; shared teams save money | C10: 5. Prices often higher than local low-cost brands
B11: 6. Support from the UK owner (PZ Cussons)
A12: EXTERNAL | B12: OPPORTUNITIES | C12: THREATS
B13: 1. Large, young and growing population | C13: 1. Naira devaluation and foreign-exchange shortages
B14: 2. Social media, e-commerce and modern retail | C14: 2. High inflation reduces what consumers can spend
B15: 3. Smaller, affordable packs for shoppers on a budget | C15: 3. Strong competition and cheap imports
B16: 4. Customers left by Unilever and P&G since 2023 | C16: 4. Fake (counterfeit) products
B17: 5. Exports to other African countries under AfCFTA | C17: 5. High energy and transport costs
B18: 6. Buying raw materials locally to cut dollar costs | C18: 6. Policy changes and insecurity
A20: SWOT count | C20: Number of points (COUNTA)
A21: Strengths | C21: =COUNTA(B6:B11) -> 6
A22: Weaknesses | C22: =COUNTA(C6:C11) -> 5
A23: Opportunities | C23: =COUNTA(B13:B18) -> 6
A24: Threats | C24: =COUNTA(C13:C18) -> 6
A25: Total | C25: =SUM(C21:C24) -> 23

Sheet SWOT Scoring
A1: SWOT SCORING: IFE AND EFE MATRICES
A2: Weight = importance (each matrix adds up to 1.00). IFE rating: strengths 3-4, weaknesses 1-2. EFE rating: how well PZ responds, 1 (poor) to 4 (superior). Weighted score = Weight × Rating; 2.50 is average.
A4: Internal Factor Evaluation (IFE): strengths and weaknesses
A5: Type | B5: Key factor | C5: Weight | D5: Rating | E5: Weighted score
A6: Strength | B6: Well-known brands such as Imperial Leather and Joy | C6: 0.15 | D6: 4 | E6: =C6*D6 -> 0.6
A7: Strength | B7: More than 100 years in Nigeria; trusted by buyers | C7: 0.1 | D7: 4 | E7: =C7*D7 -> 0.4
A8: Strength | B8: Wide distribution network across Nigeria | C8: 0.12 | D8: 3 | E8: =C8*D8 -> 0.36
A9: Strength | B9: Each business focuses on its own customers | C9: 0.08 | D9: 3 | E9: =C9*D9 -> 0.24
A10: Strength | B10: One manager per brand; shared teams save money | C10: 0.07 | D10: 3 | E10: =C10*D10 -> 0.21
A11: Strength | B11: Support from the UK owner (PZ Cussons) | C11: 0.08 | D11: 3 | E11: =C11*D11 -> 0.24
A12: Weakness | B12: Waiting for the UK owner's approval can slow work | C12: 0.08 | D12: 2 | E12: =C12*D12 -> 0.16
A13: Weakness | B13: Too many management levels can cause delays | C13: 0.07 | D13: 2 | E13: =C13*D13 -> 0.14
A14: Weakness | B14: Brands may fight over the same marketing money | C14: 0.05 | D14: 2 | E14: =C14*D14 -> 0.1
A15: Weakness | B15: Naira problems force hard decisions on imports | C15: 0.12 | D15: 1 | E15: =C15*D15 -> 0.12
A16: Weakness | B16: Prices often higher than local low-cost brands | C16: 0.08 | D16: 2 | E16: =C16*D16 -> 0.16
A17: Total | C17: =SUM(C6:C16) -> 1 | E17: =SUM(E6:E16) -> 2.73
A18: Weights check | C18: =IF(ROUND(C17,2)=1,"OK: weights add up to 1.00","Check: weights must add up to 1.00") -> OK: weights add up to 1.00
A19: Result | C19: =IF(E17>=2.5,"Above average: strengths outweigh weaknesses","Below average: weaknesses outweigh strengths") -> Above average: strengths outweigh weaknesses
A21: External Factor Evaluation (EFE): opportunities and threats
A22: Type | B22: Key factor | C22: Weight | D22: Rating | E22: Weighted score
A23: Opportunity | B23: Large, young and growing population | C23: 0.12 | D23: 3 | E23: =C23*D23 -> 0.36
A24: Opportunity | B24: Social media, e-commerce and modern retail | C24: 0.08 | D24: 2 | E24: =C24*D24 -> 0.16
A25: Opportunity | B25: Smaller, affordable packs for shoppers on a budget | C25: 0.1 | D25: 3 | E25: =C25*D25 -> 0.3
A26: Opportunity | B26: Customers left by Unilever and P&G since 2023 | C26: 0.1 | D26: 3 | E26: =C26*D26 -> 0.3
A27: Opportunity | B27: Exports to other African countries under AfCFTA | C27: 0.04 | D27: 2 | E27: =C27*D27 -> 0.08
A28: Opportunity | B28: Buying raw materials locally to cut dollar costs | C28: 0.06 | D28: 2 | E28: =C28*D28 -> 0.12
A29: Threat | B29: Naira devaluation and foreign-exchange shortages | C29: 0.14 | D29: 2 | E29: =C29*D29 -> 0.28
A30: Threat | B30: High inflation reduces what consumers can spend | C30: 0.12 | D30: 2 | E30: =C30*D30 -> 0.24
A31: Threat | B31: Strong competition and cheap imports | C31: 0.09 | D31: 3 | E31: =C31*D31 -> 0.27
A32: Threat | B32: Fake (counterfeit) products | C32: 0.05 | D32: 2 | E32: =C32*D32 -> 0.1
A33: Threat | B33: High energy and transport costs | C33: 0.06 | D33: 2 | E33: =C33*D33 -> 0.12
A34: Threat | B34: Policy changes and insecurity | C34: 0.04 | D34: 2 | E34: =C34*D34 -> 0.08
A35: Total | C35: =SUM(C23:C34) -> 1 | E35: =SUM(E23:E34) -> 2.41
A36: Weights check | C36: =IF(ROUND(C35,2)=1,"OK: weights add up to 1.00","Check: weights must add up to 1.00") -> OK: weights add up to 1.00
A37: Result | C37: =IF(E35>=2.5,"Above average: PZ responds well to opportunities and threats","Below average: PZ must respond better to opportunities and threats") -> Below average: PZ must respond better to opportunities and threats
A39: Strategic position
A40: Measure | C40: Result | E40: Excel functions
A41: Strengths score | C41: =SUMIF($A$6:$A$16,"Strength",$E$6:$E$16) -> 2.05 | E41: SUMIF
A42: Weaknesses score | C42: =SUMIF($A$6:$A$16,"Weakness",$E$6:$E$16) -> 0.68 | E42: SUMIF
A43: Opportunities score | C43: =SUMIF($A$23:$A$34,"Opportunity",$E$23:$E$34) -> 1.32 | E43: SUMIF
...

Sheet Industry Analysis
A1: INDUSTRY ANALYSIS: NIGERIAN FMCG AND CONSUMER ELECTRICALS
A2: Industry overview, Porter's Five Forces (each force rated 1 = weak to 5 = strong) and PZ's main competitors
A4: Industry overview
A5: Industry | B5: Fast-moving consumer goods (FMCG): personal care (soaps, bathing) and home care (dishwashing), plus consumer electricals
A6: Market | B6: Over 200 million people, most of them young: one of Africa's largest consumer markets
A7: Customers | B7: Households, reached through distributors, wholesalers, open markets, supermarkets and online stores
A8: Key trends | B8: Prices rising with inflation; shoppers moving to smaller packs and cheaper brands; multinationals cutting local production; more selling online and on social media
A9: Key success factors | B9: Strong brands, low costs, wide distribution, local raw materials and affordable pack sizes
A11: Porter's Five Forces
A12: Force | B12: Strength (1-5) | C12: Level | D12: Why
A13: Competitive rivalry | B13: 5 | C13: =IF(B13>=4,"High",IF(B13>=3,"Medium","Low")) -> High | D13: Many local and foreign brands fight on price, promotions and shelf space
A14: Bargaining power of buyers | B14: 4 | C14: =IF(B14>=4,"High",IF(B14>=3,"Medium","Low")) -> High | D14: Shoppers are price-sensitive and switch brands easily; big distributors bargain hard
A15: Bargaining power of suppliers | B15: 4 | C15: =IF(B15>=4,"High",IF(B15>=3,"Medium","Low")) -> High | D15: Key raw materials, packaging and parts are imported and priced in dollars
A16: Threat of substitutes | B16: 3 | C16: =IF(B16>=4,"High",IF(B16>=3,"Medium","Low")) -> Medium | D16: Cheaper unbranded and local soaps; fans instead of air conditioners
A17: Threat of new entrants | B17: 2 | C17: =IF(B17>=4,"High",IF(B17>=3,"Medium","Low")) -> Low | D17: Factories, brands and distribution cost a lot, but cheap imports still get in
A18: Average strength | B18: =AVERAGE(B13:B17) -> 3.6 | C18: =IF(B18>=3.5,"High",IF(B18>=2.5,"Medium","Low")) -> High | D18: =IF(B18>=3.5,"Strong competitive pressure: profits are hard to earn",IF(B18>=2.5,"Moderate competitive pressure","Weak competitive pressure: an attractive industry")) -> Strong competitive pressure: profits are hard to earn
A19: Strongest force | B19: =INDEX($A$13:$A$17,MATCH(MAX($B$13:$B$17),$B$13:$B$17,0)) -> Competitive rivalry
A20: Weakest force | B20: =INDEX($A$13:$A$17,MATCH(MIN($B$13:$B$17),$B$13:$B$17,0)) -> Threat of new entrants
A21: Forces rated High | B21: =COUNTIF($C$13:$C$17,"High")&" of "&COUNTA($A$13:$A$17) -> 3 of 5
A23: Main competitors
A24: Competitor | B24: Key brands | C24: Competes with PZ in | D24: Position
A25: Unilever Nigeria | B25: Vaseline, Close-Up, Pepsodent | C25: Personal care | D25: Left home care and skin cleansing (soaps) in 2023
A26: Procter & Gamble | B26: Ariel, Pampers, Always | C26: Home care | D26: Stopped making products in Nigeria; imports only (announced 2023)
A27: Reckitt Nigeria | B27: Dettol, Harpic, Jik | C27: Antiseptic soap, home care | D27: Strong in hygiene and health products
A28: Hayat Kimya | B28: Molfix, Bingo, Familia | C28: Home care | D28: Makes products locally; low prices; growing fast
A29: Local low-cost brands | B29: Many local soaps, detergents and dishwashing liquids | C29: All Family Care brands | D29: Win on price, especially in open markets
A30: LG, Samsung, Hisense, Scanfrost | B30: Air conditioners, fridges, washing machines | C30: Electrical | D30: Strong brands, plus many cheaper imports
A31: Number of competitors listed | B31: =COUNTA(A25:A30) -> 6
A33: Chart: strength of the five forces

Sheet Summary
A1: SUMMARY AND RECOMMENDATIONS
A2: The key results, linked to the other sheets: they update when any rating or weight changes
A4: Measure | B4: Result
A5: PESTLE: most important factor | B5: =PESTLE!C37 -> Economic (average score 20.7)
A6: PESTLE: highest-scoring issue | B6: =PESTLE!C39 -> Naira devaluation and FX shortages (score 25 of 25)
A7: PESTLE: high-priority issues | B7: =PESTLE!C40 -> 6 of 18 issues
A8: SWOT: points listed | B8: =SWOT!C25&" (strengths "&SWOT!C21&", weaknesses "&SWOT!C22&", opportunities "&SWOT!C23&", threats "&SWOT!C24&")" -> 23 (strengths 6, weaknesses 5, opportunities 6, threats 6)
A9: IFE total (internal strength) | B9: =TEXT('SWOT Scoring'!E17,"0.00")&" out of 4. "&'SWOT Scoring'!C19 -> 2.73 out of 4. Above average: strengths outweigh weaknesses
A10: EFE total (external response) | B10: =TEXT('SWOT Scoring'!E35,"0.00")&" out of 4. "&'SWOT Scoring'!C37 -> 2.41 out of 4. Below average: PZ must respond better to opportunities and threats
A11: Strategy (IE matrix) | B11: ='SWOT Scoring'!C48&" (cell "&'SWOT Scoring'!C47&"): "&'SWOT Scoring'!C49 -> Hold and maintain (cell V): Market penetration and product development
A12: Five Forces: average strength | B12: =TEXT('Industry Analysis'!B18,"0.0")&" out of 5. "&'Industry Analysis'!D18 -> 3.6 out of 5. Strong competitive pressure: profits are hard to earn
A13: Five Forces: strongest force | B13: ='Industry Analysis'!B19 -> Competitive rivalry
A15: Recommendations
A16: Recommendation | B16: Why
A17: 1. Buy more raw materials in Nigeria | B17: Cuts dollar costs and the damage from naira devaluation (the biggest PESTLE issue)
A18: 2. Sell smaller, affordable packs | B18: Keeps price-sensitive shoppers buying Imperial Leather, Premier Cool, Joy and Morning Fresh
A19: 3. Grow digital marketing and online sales | B19: Reaches the large young population cheaply through social media and e-commerce
A20: 4. Win customers competitors left behind | B20: Use the wide distribution network to fill shelves Unilever and P&G have left
A21: 5. Make decisions faster | B21: Give local managers more authority and cut approval levels to fix the main weaknesses
A23: Ratings and weights are the analyst's judgement, based on the company information and public news up to 2025. Check the latest figures (exchange rate, inflation) before presenting.
